Workbook

Sheet Carte
A1: Aux Saveurs Braisées · La carte
A2: Source : document « Menu Aux Saveurs Braisées - 2023 » fourni par le restaurant. Prix nets en euros, service compris.
A4: Catégorie | B4: Plat | C4: Précision | D4: Prix (€)
A5: Formules | B5: Formule midi : Entrée + Plat + Dessert | C5: Du mardi au vendredi midi, sauf jours fériés. | D5: 16.9
A6: Formules | B6: Formule midi : Entrée + Plat ou Plat + Dessert | C6: Du mardi au vendredi midi, sauf jours fériés. | D6: 14.9
A7: Formules | B7: Menu enfant : Steak / Frites | C7: Jusqu'à 10 ans. Sirop au choix, steak frites et 1 boule de glace. | D7: 9.9
A8: Formules | B8: Menu enfant : Pâtes au saumon | C8: Jusqu'à 10 ans. Sirop au choix, pâtes au saumon et 1 boule de glace. | D8: 9.9
A9: À partager | B9: Bruschetta | C9: Magret, foie gras, oignons confits. | D9: 9
A10: À partager | B10: Poulet pané | D10: 7
A11: À partager | B11: L'os à moelle | C11: Supplément foie gras : 4 €. | D11: 6
A12: À partager | B12: Trilogie de croquetas | C12: Morue, jambon, cèpes. | D12: 9
A13: À partager | B13: Ardoise de charcuterie | D13: 17
A14: À partager | B14: Œuf poché | D14: 7
A15: À partager | B15: Foie gras | D15: 13
A16: À partager | B16: Patatas bravas | D16: 5
A17: À partager | B17: Pan con tomate | C17: Supplément Serrano : 4 €. | D17: 5
A18: À partager | B18: Burrata | D18: 7
A19: Mer | B19: Couteaux | D19: 7
A20: Mer | B20: Encornets | D20: 8
A21: Mer | B21: Gambas | D21: 11
A22: Salades | B22: Salade Méditerranée | C22: Couteaux, Saint-Jacques, encornets, gambas. | D22: 16
A23: Salades | B23: Salade Gersoise | C23: Foie gras, magret grillé, gésier confit, noix. | D23: 16
A24: Salades | B24: Salade Caesar | C24: Poulet mariné, croûtons, avocat, œuf poché, parmesan. | D24: 14.5
A25: Poissons braisés & fruits de mer | B25: Saint-Jacques à la crème | C25: Accompagnement au choix : frites, pâtes, risotto ou légumes à la provençale. | D25: 25.5
A26: Poissons braisés & fruits de mer | B26: Daurade à la braise | C26: Accompagnement au choix : frites, pâtes, risotto ou légumes à la provençale. | D26: 23
A27: Poissons braisés & fruits de mer | B27: Tartare de saumon | C27: Accompagnement au choix : frites, pâtes, risotto ou légumes à la provençale. | D27: 17
A28: Poissons braisés & fruits de mer | B28: Tagliatelle au saumon | C28: Accompagnement au choix : frites, pâtes, risotto ou légumes à la provençale. | D28: 19.9
A29: Poissons braisés & fruits de mer | B29: Seiche grillée à la plancha | C29: Accompagnement au choix : frites, pâtes, risotto ou légumes à la provençale. | D29: 19
A30: Poissons braisés & fruits de mer | B30: Pavé de saumon à la braise | C30: Accompagnement au choix : frites, pâtes, risotto ou légumes à la provençale. | D30: 21
A31: Poissons braisés & fruits de mer | B31: Brochette duo Saint-Jacques et gambas | C31: Accompagnement au choix : frites, pâtes, risotto ou légumes à la provençale. | D31: 24.5
A32: Viandes | B32: Souris d'agneau (200 g) | D32: 22.5
A33: Viandes | B33: Entrecôte (280 g) | D33: 25.5
A34: Viandes | B34: Demi-magret de canard | D34: 17
A35: Viandes | B35: Tartare de bœuf | D35: 17
A36: Viandes | B36: Feuille d'entrecôte (180 g) | D36: 18
A37: Viandes | B37: Pièce du boucher | C37: Selon arrivage. | D37: 19
A38: Viandes | B38: Carpaccio de bœuf | D38: 17
A39: Viandes | B39: Carpaccio de bœuf royal | C39: Avec burrata. | D39: 19
A40: Viandes | B40: Brochette de bœuf mariné | D40: 19
A41: Viandes | B41: Brochette de poulet mariné | D41: 17
...

Sheet Résumé
A1: Résumé par catégorie
A2: Calculé à partir de l'onglet Carte : un prix modifié là-bas met ce tableau à jour. Les lignes « Sur demande » sont comptées, mais pas dans les prix.
A4: Catégorie | B4: Nombre de lignes | C4: Prix mini (€) | D4: Prix maxi (€) | E4: Prix moyen (€)
A5: Formules | B5: =COUNTIF(Carte!$A$5:$A$122,A5) -> 4 | C5: =IFERROR(_xlfn.MINIFS(Carte!$D$5:$D$122,Carte!$A$5:$A$122,A5),"-") -> 9.9 | D5: =IFERROR(_xlfn.MAXIFS(Carte!$D$5:$D$122,Carte!$A$5:$A$122,A5),"-") -> 16.9 | E5: =IFERROR(AVERAGEIFS(Carte!$D$5:$D$122,Carte!$A$5:$A$122,A5),"-") -> 12.9
A6: À partager | B6: =COUNTIF(Carte!$A$5:$A$122,A6) -> 10 | C6: =IFERROR(_xlfn.MINIFS(Carte!$D$5:$D$122,Carte!$A$5:$A$122,A6),"-") -> 5 | D6: =IFERROR(_xlfn.MAXIFS(Carte!$D$5:$D$122,Carte!$A$5:$A$122,A6),"-") -> 17 | E6: =IFERROR(AVERAGEIFS(Carte!$D$5:$D$122,Carte!$A$5:$A$122,A6),"-") -> 8.5
A7: Mer | B7: =COUNTIF(Carte!$A$5:$A$122,A7) -> 3 | C7: =IFERROR(_xlfn.MINIFS(Carte!$D$5:$D$122,Carte!$A$5:$A$122,A7),"-") -> 7 | D7: =IFERROR(_xlfn.MAXIFS(Carte!$D$5:$D$122,Carte!$A$5:$A$122,A7),"-") -> 11 | E7: =IFERROR(AVERAGEIFS(Carte!$D$5:$D$122,Carte!$A$5:$A$122,A7),"-") -> 8.6666667
A8: Salades | B8: =COUNTIF(Carte!$A$5:$A$122,A8) -> 3 | C8: =IFERROR(_xlfn.MINIFS(Carte!$D$5:$D$122,Carte!$A$5:$A$122,A8),"-") -> 14.5 | D8: =IFERROR(_xlfn.MAXIFS(Carte!$D$5:$D$122,Carte!$A$5:$A$122,A8),"-") -> 16 | E8: =IFERROR(AVERAGEIFS(Carte!$D$5:$D$122,Carte!$A$5:$A$122,A8),"-") -> 15.5
A9: Poissons braisés & fruits de mer | B9: =COUNTIF(Carte!$A$5:$A$122,A9) -> 7 | C9: =IFERROR(_xlfn.MINIFS(Carte!$D$5:$D$122,Carte!$A$5:$A$122,A9),"-") -> 17 | D9: =IFERROR(_xlfn.MAXIFS(Carte!$D$5:$D$122,Carte!$A$5:$A$122,A9),"-") -> 25.5 | E9: =IFERROR(AVERAGEIFS(Carte!$D$5:$D$122,Carte!$A$5:$A$122,A9),"-") -> 21.414286
A10: Viandes | B10: =COUNTIF(Carte!$A$5:$A$122,A10) -> 11 | C10: =IFERROR(_xlfn.MINIFS(Carte!$D$5:$D$122,Carte!$A$5:$A$122,A10),"-") -> 17 | D10: =IFERROR(_xlfn.MAXIFS(Carte!$D$5:$D$122,Carte!$A$5:$A$122,A10),"-") -> 25.5 | E10: =IFERROR(AVERAGEIFS(Carte!$D$5:$D$122,Carte!$A$5:$A$122,A10),"-") -> 19.1
A11: Burgers braisés | B11: =COUNTIF(Carte!$A$5:$A$122,A11) -> 3 | C11: =IFERROR(_xlfn.MINIFS(Carte!$D$5:$D$122,Carte!$A$5:$A$122,A11),"-") -> 14 | D11: =IFERROR(_xlfn.MAXIFS(Carte!$D$5:$D$122,Carte!$A$5:$A$122,A11),"-") -> 17 | E11: =IFERROR(AVERAGEIFS(Carte!$D$5:$D$122,Carte!$A$5:$A$122,A11),"-") -> 15.333333
A12: Desserts | B12: =COUNTIF(Carte!$A$5:$A$122,A12) -> 10 | C12: =IFERROR(_xlfn.MINIFS(Carte!$D$5:$D$122,Carte!$A$5:$A$122,A12),"-") -> 6 | D12: =IFERROR(_xlfn.MAXIFS(Carte!$D$5:$D$122,Carte!$A$5:$A$122,A12),"-") -> 13 | E12: =IFERROR(AVERAGEIFS(Carte!$D$5:$D$122,Carte!$A$5:$A$122,A12),"-") -> 8.15
A13: Glaces & sorbets | B13: =COUNTIF(Carte!$A$5:$A$122,A13) -> 7 | C13: =IFERROR(_xlfn.MINIFS(Carte!$D$5:$D$122,Carte!$A$5:$A$122,A13),"-") -> 2.9 | D13: =IFERROR(_xlfn.MAXIFS(Carte!$D$5:$D$122,Carte!$A$5:$A$122,A13),"-") -> 8 | E13: =IFERROR(AVERAGEIFS(Carte!$D$5:$D$122,Carte!$A$5:$A$122,A13),"-") -> 5.9571429
A14: Vins rouges | B14: =COUNTIF(Carte!$A$5:$A$122,A14) -> 10 | C14: =IFERROR(_xlfn.MINIFS(Carte!$D$5:$D$122,Carte!$A$5:$A$122,A14),"-") -> 4.5 | D14: =IFERROR(_xlfn.MAXIFS(Carte!$D$5:$D$122,Carte!$A$5:$A$122,A14),"-") -> 32 | E14: =IFERROR(AVERAGEIFS(Carte!$D$5:$D$122,Carte!$A$5:$A$122,A14),"-") -> 15.95
A15: Vins rosés | B15: =COUNTIF(Carte!$A$5:$A$122,A15) -> 4 | C15: =IFERROR(_xlfn.MINIFS(Carte!$D$5:$D$122,Carte!$A$5:$A$122,A15),"-") -> 4.5 | D15: =IFERROR(_xlfn.MAXIFS(Carte!$D$5:$D$122,Carte!$A$5:$A$122,A15),"-") -> 23 | E15: =IFERROR(AVERAGEIFS(Carte!$D$5:$D$122,Carte!$A$5:$A$122,A15),"-") -> 15.125
A16: Vins blancs | B16: =COUNTIF(Carte!$A$5:$A$122,A16) -> 5 | C16: =IFERROR(_xlfn.MINIFS(Carte!$D$5:$D$122,Carte!$A$5:$A$122,A16),"-") -> 4.5 | D16: =IFERROR(_xlfn.MAXIFS(Carte!$D$5:$D$122,Carte!$A$5:$A$122,A16),"-") -> 19 | E16: =IFERROR(AVERAGEIFS(Carte!$D$5:$D$122,Carte!$A$5:$A$122,A16),"-") -> 11.1
... A21: Boissons sans alcool | B21: =COUNTIF(Carte!$A$5:$A$122,A21) -> 10 | C21: =IFERROR(_xlfn.MINIFS(Carte!$D$5:$D$122,Carte!$A$5:$A$122,A21),"-") -> 1.7 | D21: =IFERROR(_xlfn.MAXIFS(Carte!$D$5:$D$122,Carte!$A$5:$A$122,A21),"-") -> 5.9 | E21: =IFERROR(AVERAGEIFS(Carte!$D$5:$D$122,Carte!$A$5:$A$122,A21),"-") -> 3.26
A22: Total | B22: =SUM(B5:B21) -> 118
